[ERROR 2023-01-31 14:48:48] : Exception: woops
Traceback (most recent call last):
  File "/Users/yves/Desktop/toolbox/toolbox/_handle/_exception_handler.py", line 58, in wrapper
    func(*args, **kwargs)
  File "/Users/yves/Desktop/toolbox/tests/test_handle.py", line 47, in woops
    raise Exception('woops')
Exception: woops
[ERROR 2023-01-31 16:22:22] : Exception: woops
Traceback (most recent call last):
  File "/Users/yves/Desktop/toolbox/toolbox/_handle/_exception_handler.py", line 58, in wrapper
    func(*args, **kwargs)
  File "/Users/yves/Desktop/toolbox/tests/test_handle.py", line 47, in woops
    raise Exception('woops')
Exception: woops
